Workbook

Sheet Sheet1
A1: S.no | B1: Component | C1: Object description | D1: Wilo article number | E1: Unit price
A2: 1 | B2: 2041901 | C2: O-RING 412X7 ISO361B EPDM | E2: =VLOOKUP(B2,Sheet2!$A$1:$D$650,3,FALSE) -> 1.56
A3: 2 | B3: 2056450 | C3: SCREW PLUG DIN96 R3/8"-A2 | E3: =VLOOKUP(B3,Sheet2!$A$1:$D$650,3,FALSE) -> 0.71
A4: 3 | B4: 2082776 | C4: O-RING 224X3,55 ISO361B EPDM | E4: =VLOOKUP(B4,Sheet2!$A$1:$D$650,3,FALSE) -> 0.93
A5: 4 | B5: 2082778 | C5: O-RING 338X5,3 ISO361B EPDM | E5: =VLOOKUP(B5,Sheet2!$A$1:$D$650,3,FALSE) -> 401.56
A6: 5 | B6: 2109329 | C6: WASHER FST VZ M6 NZG | E6: =VLOOKUP(B6,Sheet2!$A$1:$D$650,3,FALSE) -> 0.2
A7: 6 | B7: 2141016 | C7: PH.B32/16.1-P223 16 GG KTL MX | E7: =VLOOKUP(B7,Sheet2!$A$1:$D$650,3,FALSE) -> 43.6184
A8: 7 | B8: 2141028 | C8: PH.B32/125-P188 16 GG KTL MX | E8: =VLOOKUP(B8,Sheet2!$A$1:$D$650,3,FALSE) -> 39.4044
A9: 8 | B9: 2141032 | C9: PH.B32/16-P223 16 GG KTL MX | E9: =VLOOKUP(B9,Sheet2!$A$1:$D$650,3,FALSE) -> 43.421
A10: 9 | B10: 2141036 | C10: PH.B32/2-P253 16 GG KTL MX | E10: =VLOOKUP(B10,Sheet2!$A$1:$D$650,3,FALSE) -> 51.7132
A11: 10 | B11: 2141040 | C11: PH.B32/25-P36 16 GG KTL MX | E11: =VLOOKUP(B11,Sheet2!$A$1:$D$650,3,FALSE) -> 62.594
A12: 11 | B12: 2141044 | C12: PH.B4/125-P188 16 GG KTL MX | E12: =VLOOKUP(B12,Sheet2!$A$1:$D$650,3,FALSE) -> 47.1324
A13: 12 | B13: 2141048 | C13: PH.B4/16-P223 16 GG KTL MX | E13: =VLOOKUP(B13,Sheet2!$A$1:$D$650,3,FALSE) -> 45.5392
... A529: 528 | B529: 9075030 | C529: 1/2 Steel CPL Guard 320x235x117-R60 | E529: =VLOOKUP(B529,Sheet2!$A$1:$D$650,3,FALSE) -> 10

Sheet Sheet3
A1: S.no | B1: Component | C1: Object description | D1: Wilo article number | E1: Unit price
A2: 101 | B2: 2141476 | C2: Impeller 32/125-15-85/22 1.448 fin MX
A3: 102 | B3: 2141478 | C3: Impeller 32/16-174-84/22 1.448 fin MX
A4: 103 | B4: 2141482 | C4: Impeller 32/25-264-96/22 1.448 fin MX
A5: 104 | B5: 2141484 | C5: Impeller 4/125-15-11/22 1.448 fin MX
A6: 105 | B6: 2141486 | C6: Impeller 4/16-181-84/22 1.448 fin MX
A7: 106 | B7: 2141488 | C7: Impeller 4/2-215-84/22 1.448 fin MX
A8: 107 | B8: 2141490 | C8: Impeller 4/25-256-15/22 1.448 fin MX
A9: 108 | B9: 2141492 | C9: Impeller 4/315-338-11/3 1.448 fin MX
A10: 109 | B10: 2141494 | C10: Impeller 5/125-15-11/22 1.448 fin MX
A11: 110 | B11: 2141496 | C11: Impeller 5/16-189-12/22 1.448 fin MX
A12: 111 | B12: 2141498 | C12: mpeller 5/2-224-115/22 1.448 fin MX
A13: 112 | B13: 2141502 | C13: Impeller 5/315-329-11/3 1.448 fin MX
... A88: 528 | B88: 9075030 | C88: 1/2 Steel CPL Guard 320x235x117-R60

Sheet Sheet2
A1: items | B1: description | C1: USD | D1: Supplier
A2: 9001669 | B2: Iron Cushion BDT100x50-20 | C2: 5 | D2: WCN
A3: 9001672 | B3: Iron Cushion BDT125x65-20 Q235 | C3: 4.47 | D3: WCN
A4: 9001675 | B4: Iron Cushion BDT160x80-25 Q235 | C4: 5.84 | D4: WCN
A5: 9001676 | B5: Iron Cushion BDT160x80-30 Q235 | C5: 5.62 | D5: WCN
A6: 9001681 | B6: Iron Cushion ZJDT160x60-20 Q235 | C6: 5.05 | D6: WCN
A7: 9001683 | B7: Iron Cushion ZJDT160x60-45 Q235 | C7: 11.04 | D7: WCN
A8: 9001686 | B8: Iron Cushion ZJDT160x80-50 Q235 | C8: 10.88 | D8: WCN
A9: 9001687 | B9: Iron Cushion ZJDT160x80-55 Q235 | C9: 10.22 | D9: WCN
A10: 9001688 | B10: Iron Cushion ZJDT160x80-80 Q235 | C10: 15.16 | D10: WCN
A11: 9001689 | B11: Iron Cushion ZJDT160x80-90 Q235 | C11: 15.7 | D11: WCN
A12: 9003050 | B12: Iron Cushion BDT-50 400x160x50 Q235 | C12: 28.27 | D12: WCN
A13: 9003051 | B13: Iron Cushion BDT-65 400x160x65 Q235 | C13: 44.34 | D13: WCN
... A88: 9049957 | B88: Drilled Iron Cushion DJDT90L-70 | C88: 10.03 | D88: WCN
A89: 9049958 | B89: Drilled Iron Cushion DJDT90L-90 | C89: 10.31 | D89: WCN
A90: 9049959 | B90: Drilled Iron Cushion DJDT90S-110 | C90: 11.52 | D90: WCN
A91: 9049960 | B91: Drilled Iron Cushion DJDT90S-22 | C91: 3.70 | D91: WCN
A92: 9049961 | B92: Drilled Iron Cushion DJDT90S-42 | C92: 7.89 | D92: WCN
A93: 9049962 | B93: Drilled Iron Cushion DJDT90S-70 | C93: 10.03 | D93: WCN
A94: 9049963 | B94: Drilled Iron Cushion DJDT90S-90 | C94: 11.23 | D94: WCN
A95: 9049965 | B95: Iron Cushion BDT240x100-28 | C95: 8.41 | D95: WCN
A96: 9049966 | B96: Iron Cushion BDT265x100-20 | C96: 8.04 | D96: WCN
A97: 9049968 | B97: Iron Cushion BDT345x125-25 | C97: 18 | D97: WCN
A98: 9049969 | B98: Iron Cushion BDT265x100-40 | C98: 20.34 | D98: WCN
A99: 9049972 | B99: Iron Cushion BDT345x125-70 | C99: 25.85 | D99: WCN
A100: 9049973 | B100: Iron Cushion BDT345x125-20 | C100: 10.53 | D100: WCN
A101: 9049974 | B101: Iron Cushion BDT400x160-30 | C101: 16.05 | D101: WCN
A102: 9049975 | B102: Iron Cushion BDT550x200-35 | C102: 35.82 | D102: WCN
A103: 9049977 | B103: Iron Cushion BDT500x200-35 | C103: 38.9 | D103: WCN
A104: 9049978 | B104: Iron Cushion ZJDT160x60-28 | C104: 5.07 | D104: WCN
A105: 9049979 | B105: Iron Cushion ZJDT160x60-40 | C105: 13.42 | D105: WCN
A106: 9049981 | B106: Iron Cushion ZJDT160x60-20 | C106: 3.08 | D106: WCN
A107: 9049984 | B107: Iron Cushion ZJDT160x60-35 | C107: 6.84 | D107: WCN
A108: 9049987 | B108: Iron Cushion BDT345x125-55 | C108: 22.63 | D108: WCN
... A203: 2212307 | B203: m.seal eMG12/28-G6 AQ7EGG | C203: 20.61 | D203: Vulcan
A204: 9002952 | B204: Bearing 6311-2Z/C3-SKF | C204: =102/3.67 -> 27.792916 | D204: cangzhou hongyuan
A205: 9003518 | B205: Bearing 6308-2Z/C3-SKF | C205: =41.5/3.67 -> 11.307902 | D205: cangzhou hongyuan
A206: 9066946 | B206: Bearing 6306-C-2Z-L069-C3 FAG | C206: 7.3 | D206: cangzhou hongyuan
A207: 4049642 | B207: CIRCLIPS I 120x4 | C207: 1.21 | D207: beijing youqiang
A208: 6085059 | B208: circlips 90x3 DIN472 FST | C208: 0.38 | D208: beijing youqiang
...
